Workbook
Name Users: Categories!$B$2:$B$15

Sheet Company lists
T1: =SUM(Table3[Column1]) -> 0 | U1: =SUM(Table3[Industry Essentials]) -> 1179 | V1: =SUM(Table3[Energy Supply Market Intelligence]) -> 244 | W1: =SUM(Table3[Energy Supply RTM Analysis]) -> 272 | X1: =SUM(Table3[Energy Supply Forecasts]) -> 244 | Y1: =SUM(Table3[Energy Supply Regulation]) -> 140 | Z1: =SUM(Table3[Renewables Market Intelligence]) -> 553 | AA1: =SUM(Table3[Renewables RTM Analysis]) -> 429 | AB1: =SUM(Table3[Renewables Forecasts]) -> 553 | AC1: =SUM(Table3[Renewables Regulation]) -> 382 | AD1: =SUM(Table3[Flexibility Market Intelligence]) -> 527 | AE1: =SUM(Table3[Flexibility RTM Analysis]) -> 268 | AF1: =SUM(Table3[Flexibility Forecasts]) -> 461 | AG1: =SUM(Table3[Flexibility Regulation]) -> 228 | AH1: =SUM(Table3[Business Energy Essentials]) -> 522 | AI1: =SUM(Table3[Energy User RTM Analysis]) -> 587 | AJ1: =SUM(Table3[Energy User Forecasts]) -> 531
A2: Company name | B2: CI subs customer? (existing and past 2 years) | C2: Consulting client? (past 2 years) | D2: Date added | E2: Scale | F2: Column19 | G2: Strategic priority segment | H2: Product fit | I2: Brand reach | J2: Competitive advantage | K2: Propensity to buy/ buyer readiness | L2: Overall scoring priority | M2: CI Segment | N2: Primary theme/sector | O2: Secondary theme/sector (1) | P2: Secondary theme/sector (2) | Q2: Secondary theme/sector (3) | R2: Secondary theme/sector (4) | S2: Secondary theme/sector (5) | T2: Column1 | U2: Industry Essentials | V2: Energy Supply Market Intelligence | W2: Energy Supply RTM Analysis | X2: Energy Supply Forecasts | Y2: Energy Supply Regulation | Z2: Renewables Market Intelligence | AA2: Renewables RTM Analysis | AB2: Renewables Forecasts | AC2: Renewables Regulation | AD2: Flexibility Market Intelligence | AE2: Flexibility RTM Analysis | AF2: Flexibility Forecasts | AG2: Flexibility Regulation | AH2: Business Energy Essentials | AI2: Energy User RTM Analysis | AJ2: Energy User Forecasts | AK2: Energy User Regulation | AL2: Column2 | AM2: Column3 | AN2: Column4 | AO2: Column5 | AP2: Column6 | AQ2: Column7 | AR2: Column8 | AS2: Column9 | AT2: Column10 | AU2: Column11 | AV2: Column12 | AW2: Column13 | AX2: Column14 | AY2: Column15 | AZ2: Column16 | BA2: Column17 | BB2: Column18 | BC2: Total Spend | BD2: Multiplier
A3: British Gas Trading Ltd | B3: Yes | D3: 45566 | E3: Large | F3: =INDEX(Definitions!$G$13:$G$17,MATCH(Table3[[#This Row],[Propensity to buy/ buyer readiness]],Definitions!$A$13:$A$17,0)) -> 250000 | G3: 5 | H3: 5 | I3: 5 | J3: 5 | K3: 5 | L3: =SUM(Table3[[#This Row],[Strategic priority segment]:[Propensity to buy/ buyer readiness]]) -> 25 | M3: Energy Supply | N3: Energy supplier | O3: Renewables generator/developer | P3: Flexibility generator/developer | Q3: Energy traders | U3: 1 | V3: 1 | W3: 1 | X3: 1 | Y3: 1 | Z3: 1 | AA3: 1 | AB3: 1 | AC3: 1 | AD3: 1 | AE3: 1 | AF3: 1 | AG3: 1 | AH3: 0 | AI3: 0 | AJ3: 0 | AK3: 0 | AL3: {=_xlfn.IFS(AND(Table3[[#This Row],[Scale]:[Scale]]="Large",Table3[[#This Row],[Industry Essentials]]=1),INDEX(Definitions!$C$21:$C$37,MATCH(Table3[[#Headers],[Industry Essentials]],Definitions!$A$21:$A$37,0)),AND(Table3[[#This Row],[Scale]:[Scale]]="Small",Table3[[#This Row],[Industry Essentials]]=1),INDEX(Definitions!$B$21:$B$37,MATCH(Table3[[#Headers],[Industry Essentials]],Definitions!$A$21:$A$37,0)),Table3[[#This Row],[Industry Essentials]]=0,0)} -> 10800 | AM3: {=_xlfn.IFS(AND(Table3[[#This Row],[Scale]:[Scale]]="Large",Table3[[#This Row],[Energy Supply Market Intelligence]]=1),INDEX(Definitions!$C$21:$C$37,MATCH(Table3[[#Headers],[Energy Supply Market Intelligence]],Definitions!$A$21:$A$37,0)),AND(Table3[[#This Row],[Scale]:[Scale]]="Small",Table3[[#This Row],[Energy Supply Market Intelligence]]=1),INDEX(Definitions!$B$21:$B$37,MATCH(Table3[[#Headers],[Energy Supply Market Intelligence]],Definitions!$A$21:$A$37,0)),Table3[[#This Row],[Energy Supply Market Intelligence]]=0,0)} -> 43200 | AN3: {=_xlfn.IFS(AND(Table3[[#This Row],[Scale]:[Scale]]="Large",Table3[[#This Row],[Energy Supply RTM Analysis]]=1),INDEX(Definitions!$C$21:$C$37,MATCH(Table3[[#Headers],[Energy Supply RTM Analysis]],Definitions!$A$21:$A$37,0)),AND(Table3[[#This Row],[Scale]:[Scale]]="Small",Table3[[#This Row],[Energy Supply RTM Analysis]]=1),INDEX(Definitions!$B$21:$B$37,MATCH(Table3[[#Headers],[Energy Supply RTM Analysis]],Definitions!$A$21:$A$37,0)),Table3[[#This Row],[Energy Supply RTM Analysis]]=0,0)} -> 73800 | AO3: {=_xlfn.IFS(AND(Table3[[#This Row],[Scale]:[Scale]]="Large",Table3[[#This Row],[Energy Supply Forecasts]]=1),INDEX(Definitions!$C$21:$C$37,MATCH(Table3[[#Headers],[Energy Supply Forecasts]],Definitions!$A$21:$A$37,0)),AND(Table3[[#This Row],[Scale]:[Scale]]="Small",Table3[[#This Row],[Energy Supply Forecasts]]=1),INDEX(Definitions!$B$21:$B$37,MATCH(Table3[[#Headers],[Energy Supply Forecasts]],Definitions!$A$21:$A$37,0)),Table3[[#This Row],[Energy Supply Forecasts]]=0,0)} -> 48600 | AP3: {=_xlfn.IFS(AND(Table3[[#This Row],[Scale]:[Scale]]="Large",Table3[[#This Row],[Energy Supply Regulation]]=1),INDEX(Definitions!$C$21:$C$37,MATCH(Table3[[#Headers],[Energy Supply Regulation]],Definitions!$A$21:$A$37,0)),AND(Table3[[#This Row],[Scale]:[Scale]]="Small",Table3[[#This Row],[Energy Supply Regulation]]=1),INDEX(Definitions!$B$21:$B$37,MATCH(Table3[[#Headers],[Energy Supply Regulation]],Definitions!$A$21:$A$37,0)),Table3[[#This Row],[Energy Supply Regulation]]=0,0)} -> 55800 | AQ3: {=_xlfn.IFS(AND(Table3[[#This Row],[Scale]:[Scale]]="Large",Table3[[#This Row],[Renewables Market Intelligence]]=1),INDEX(Definitions!$C$21:$C$37,MATCH(Table3[[#Headers],[Renewables Market Intelligence]],Definitions!$A$21:$A$37,0)),AND(Table3[[#This Row],[Scale]:[Scale]]="Small",Table3[[#This Row],[Renewables Market Intelligence]]=1),INDEX(Definitions!$B$21:$B$37,MATCH(Table3[[#Headers],[Renewables Market Intelligence]],Definitions!$A$21:$A$37,0)),Table3[[#This Row],[Renewables Market Intelligence]]=0,0)} -> 23400 | AR3: {=_xlfn.IFS(AND(Table3[[#This Row],[Scale]:[Scale]]="Large",Table3[[#This Row],[Renewables RTM Analysis]]=1),INDEX(Definitions!$C$21:$C$37,MATCH(Table3[[#Headers],[Renewables RTM Analysis]],Definitions!$A$21:$A$37,0)),AND(Table3[[#This Row],[Scale]:[Scale]]="Small",Table3[[#This Row],[Renewables RTM Analysis]]=1),INDEX(Definitions!$B$21:$B$37,MATCH(Table3[[#Headers],[Renewables RTM Analysis]],Definitions!$A$21:$A$37,0)),Table3[[#This Row],[Renewables RTM Analysis]]=0,0)} -> 20700 | AS3: {=_xlfn.IFS(AND(Table3[[#This Row],[Scale]:[Scale]]="Large",Table3[[#This Row],[Renewables Forecasts]]=1),INDEX(Definitions!$C$21:$C$37,MATCH(Table3[[#Headers],[Renewables Forecasts]],Definitions!$A$21:$A$37,0)),AND(Table3[[#This Row],[Scale]:[Scale]]="Small",Table3[[#This Row],[Renewables Forecasts]]=1),INDEX(Definitions!$B$21:$B$37,MATCH(Table3[[#Headers],[Renewables Forecasts]],Definitions!$A$21:$A$37,0)),Table3[[#This Row],[Renewables Forecasts]]=0,0)} -> 59400 | AT3: {=_xlfn.IFS(AND(Table3[[#This Row],[Scale]:[Scale]]="Large",Table3[[#This Row],[Renewables Regulation]]=1),INDEX(Definitions!$C$21:$C$37,MATCH(Table3[[#Headers],[Renewables Regulation]],Definitions!$A$21:$A$37,0)),AND(Table3[[#This Row],[Scale]:[Scale]]="Small",Table3[[#This Row],[Renewables Regulation]]=1),INDEX(Definitions!$B$21:$B$37,MATCH(Table3[[#Headers],[Renewables Regulation]],Definitions!$A$21:$A$37,0)),Table3[[#This Row],[Renewables Regulation]]=0,0)} -> 26100 | AU3: {=_xlfn.IFS(AND(Table3[[#This Row],[Scale]:[Scale]]="Large",Table3[[#This Row],[Flexibility Market Intelligence]]=1),INDEX(Definitions!$C$21:$C$37,MATCH(Table3[[#Headers],[Flexibility Market Intelligence]],Definitions!$A$21:$A$37,0)),AND(Table3[[#This Row],[Scale]:[Scale]]="Small",Table3[[#This Row],[Flexibility Market Intelligence]]=1),INDEX(Definitions!$B$21:$B$37,MATCH(Table3[[#Headers],[Flexibility Market Intelligence]],Definitions!$A$21:$A$37,0)),Table3[[#This Row],[Flexibility Market Intelligence]]=0,0)} -> 29700 | AV3: {=_xlfn.IFS(AND(Table3[[#This Row],[Scale]:[Scale]]="Large",Table3[[#This Row],[Flexibility RTM Analysis]]=1),INDEX(Definitions!$C$21:$C$37,MATCH(Table3[[#Headers],[Flexibility RTM Analysis]],Definitions!$A$21:$A$37,0)),AND(Table3[[#This Row],[Scale]:[Scale]]="Small",Table3[[#This Row],[Flexibility RTM Analysis]]=1),INDEX(Definitions!$B$21:$B$37,MATCH(Table3[[#Headers],[Flexibility RTM Analysis]],Definitions!$A$21:$A$37,0)),Table3[[#This Row],[Flexibility RTM Analysis]]=0,0)} -> 10800 | AW3: {=_xlfn.IFS(AND(Table3[[#This Row],[Scale]:[Scale]]="Large",Table3[[#This Row],[Flexibility Forecasts]]=1),INDEX(Definitions!$C$21:$C$37,MATCH(Table3[[#Headers],[Flexibility Forecasts]],Definitions!$A$21:$A$37,0)),AND(Table3[[#This Row],[Scale]:[Scale]]="Small",Table3[[#This Row],[Flexibility Forecasts]]=1),INDEX(Definitions!$B$21:$B$37,MATCH(Table3[[#Headers],[Flexibility Forecasts]],Definitions!$A$21:$A$37,0)),Table3[[#This Row],[Flexibility Forecasts]]=0,0)} -> 44100 | AX3: {=_xlfn.IFS(AND(Table3[[#This Row],[Scale]:[Scale]]="Large",Table3[[#This Row],[Flexibility Regulation]]=1),INDEX(Definitions!$C$21:$C$37,MATCH(Table3[[#Headers],[Flexibility Regulation]],Definitions!$A$21:$A$37,0)),AND(Table3[[#This Row],[Scale]:[Scale]]="Small",Table3[[#This Row],[Flexibility Regulation]]=1),INDEX(Definitions!$B$21:$B$37,MATCH(Table3[[#Headers],[Flexibility Regulation]],Definitions!$A$21:$A$37,0)),Table3[[#This Row],[Flexibility Regulation]]=0,0)} -> 36000 | AY3: {=_xlfn.IFS(AND(Table3[[#This Row],[Scale]:[Scale]]="Large",Table3[[#This Row],[Business Energy Essentials]]=1),INDEX(Definitions!$C$21:$C$37,MATCH(Table3[[#Headers],[Business Energy Essentials]],Definitions!$A$21:$A$37,0)),AND(Table3[[#This Row],[Scale]:[Scale]]="Small",Table3[[#This Row],[Business Energy Essentials]]=1),INDEX(Definitions!$B$21:$B$37,MATCH(Table3[[#Headers],[Business Energy Essentials]],Definitions!$A$21:$A$37,0)),Table3[[#This Row],[Business Energy Essentials]]=0,0)} -> 0 | AZ3: {=_xlfn.IFS(AND(Table3[[#This Row],[Scale]:[Scale]]="Large",Table3[[#This Row],[Energy User RTM Analysis]]=1),INDEX(Definitions!$C$21:$C$37,MATCH(Table3[[#Headers],[Energy User RTM Analysis]],Definitions!$A$21:$A$37,0)),AND(Table3[[#This Row],[Scale]:[Scale]]="Small",Table3[[#This Row],[Energy User RTM Analysis]]=1),INDEX(Definitions!$B$21:$B$37,MATCH(Table3[[#Headers],[Energy User RTM Analysis]],Definitions!$A$21:$A$37,0)),Table3[[#This Row],[Energy User RTM Analysis]]=0,0)} -> 0 | BA3: {=_xlfn.IFS(AND(Table3[[#This Row],[Scale]:[Scale]]="Large",Table3[[#This Row],[Energy User Forecasts]]=1),INDEX(Definitions!$C$21:$C$37,MATCH(Table3[[#Headers],[Energy User Forecasts]],Definitions!$A$21:$A$37,0)),AND(Table3[[#This Row],[Scale]:[Scale]]="Small",Table3[[#This Row],[Energy User Forecasts]]=1),INDEX(Definitions!$B$21:$B$37,MATCH(Table3[[#Headers],[Energy User Forecasts]],Definitions!$A$21:$A$37,0)),Table3[[#This Row],[Energy User Forecasts]]=0,0)} -> 0 | BB3: {=_xlfn.IFS(AND(Table3[[#This Row],[Scale]:[Scale]]="Large",Table3[[#This Row],[Energy User Regulation]]=1),INDEX(Definitions!$C$21:$C$37,MATCH(Table3[[#Headers],[Energy User Regulation]],Definitions!$A$21:$A$37,0)),AND(Table3[[#This Row],[Scale]:[Scale]]="Small",Table3[[#This Row],[Energy User Regulation]]=1),INDEX(Definitions!$B$21:$B$37,MATCH(Table3[[#Headers],[Energy User Regulation]],Definitions!$A$21:$A$37,0)),Table3[[#This Row],[Energy User Regulation]]=0,0)} -> 0 | BC3: =IF(SUM(Table3[[#This Row],[Column2]:[Column18]])>Table3[[#This Row],[Column19]],Table3[[#This Row],[Column19]],SUM(Table3[[#This Row],[Column2]:[Column18]])) -> 250000 | BD3: =Table3[[#This Row],[Total Spend]]/SUM(Table3[[#This Row],[Column2]:[Column18]]) -> 0.51824212
A4: Centrica Energy Limited | B4: Yes | C4: Yes | D4: 45566 | E4: Large | F4: =INDEX(Definitions!$G$13:$G$17,MATCH(Table3[[#This Row],[Propensity to buy/ buyer readiness]],Definitions!$A$13:$A$17,0)) -> 250000 | G4: 5 | H4: 5 | I4: 5 | J4: 5 | K4: 5 | L4: =SUM(Table3[[#This Row],[Strategic priority segment]:[Propensity to buy/ buyer readiness]]) -> 25 | M4: Energy Supply | N4: Energy supplier | O4: Renewables generator/developer | P4: Flexibility generator/developer | Q4: Energy traders | U4: 1 | V4: 1 | W4: 1 | X4: 1 | Y4: 1 | Z4: 1 | AA4: 1 | AB4: 1 | AC4: 1 | AD4: 1 | AE4: 1 | AF4: 1 | AG4: 1 | AH4: 0 | AI4: 0 | AJ4: 0 | AK4: 0 | AL4: {=_xlfn.IFS(AND(Table3[[#This Row],[Scale]:[Scale]]="Large",Table3[[#This Row],[Industry Essentials]]=1),INDEX(Definitions!$C$21:$C$37,MATCH(Table3[[#Headers],[Industry Essentials]],Definitions!$A$21:$A$37,0)),AND(Table3[[#This Row],[Scale]:[Scale]]="Small",Table3[[#This Row],[Industry Essentials]]=1),INDEX(Definitions!$B$21:$B$37,MATCH(Table3[[#Headers],[Industry Essentials]],Definitions!$A$21:$A$37,0)),Table3[[#This Row],[Industry Essentials]]=0,0)} -> 10800 | AM4: {=_xlfn.IFS(AND(Table3[[#This Row],[Scale]:[Scale]]="Large",Table3[[#This Row],[Energy Supply Market Intelligence]]=1),INDEX(Definitions!$C$21:$C$37,MATCH(Table3[[#Headers],[Energy Supply Market Intelligence]],Definitions!$A$21:$A$37,0)),AND(Table3[[#This Row],[Scale]:[Scale]]="Small",Table3[[#This Row],[Energy Supply Market Intelligence]]=1),INDEX(Definitions!$B$21:$B$37,MATCH(Table3[[#Headers],[Energy Supply Market Intelligence]],Definitions!$A$21:$A$37,0)),Table3[[#This Row],[Energy Supply Market Intelligence]]=0,0)} -> 43200 | AN4: {=_xlfn.IFS(AND(Table3[[#This Row],[Scale]:[Scale]]="Large",Table3[[#This Row],[Energy Supply RTM Analysis]]=1),INDEX(Definitions!$C$21:$C$37,MATCH(Table3[[#Headers],[Energy Supply RTM Analysis]],Definitions!$A$21:$A$37,0)),AND(Table3[[#This Row],[Scale]:[Scale]]="Small",Table3[[#This Row],[Energy Supply RTM Analysis]]=1),INDEX(Definitions!$B$21:$B$37,MATCH(Table3[[#Headers],[Energy Supply RTM Analysis]],Definitions!$A$21:$A$37,0)),Table3[[#This Row],[Energy Supply RTM Analysis]]=0,0)} -> 73800 | AO4: {=_xlfn.IFS(AND(Table3[[#This Row],[Scale]:[Scale]]="Large",Table3[[#This Row],[Energy Supply Forecasts]]=1),INDEX(Definitions!$C$21:$C$37,MATCH(Table3[[#Headers],[Energy Supply Forecasts]],Definitions!$A$21:$A$37,0)),AND(Table3[[#This Row],[Scale]:[Scale]]="Small",Table3[[#This Row],[Energy Supply Forecasts]]=1),INDEX(Definitions!$B$21:$B$37,MATCH(Table3[[#Headers],[Energy Supply Forecasts]],Definitions!$A$21:$A$37,0)),Table3[[#This Row],[Energy Supply Forecasts]]=0,0)} -> 48600 | AP4: {=_xlfn.IFS(AND(Table3[[#This Row],[Scale]:[Scale]]="Large",Table3[[#This Row],[Energy Supply Regulation]]=1),INDEX(Definitions!$C$21:$C$37,MATCH(Table3[[#Headers],[Energy Supply Regulation]],Definitions!$A$21:$A$37,0)),AND(Table3[[#This Row],[Scale]:[Scale]]="Small",Table3[[#This Row],[Energy Supply Regulation]]=1),INDEX(Definitions!$B$21:$B$37,MATCH(Table3[[#Headers],[Energy Supply Regulation]],Definitions!$A$21:$A$37,0)),Table3[[#This Row],[Energy Supply Regulation]]=0,0)} -> 55800 | AQ4: {=_xlfn.IFS(AND(Table3[[#This Row],[Scale]:[Scale]]="Large",Table3[[#This Row],[Renewables Market Intelligence]]=1),INDEX(Definitions!$C$21:$C$37,MATCH(Table3[[#Headers],[Renewables Market Intelligence]],Definitions!$A$21:$A$37,0)),AND(Table3[[#This Row],[Scale]:[Scale]]="Small",Table3[[#This Row],[Renewables Market Intelligence]]=1),INDEX(Definitions!$B$21:$B$37,MATCH(Table3[[#Headers],[Renewables Market Intelligence]],Definitions!$A$21:$A$37,0)),Table3[[#This Row],[Renewables Market Intelligence]]=0,0)} -> 23400 | AR4: {=_xlfn.IFS(AND(Table3[[#This Row],[Scale]:[Scale]]="Large",Table3[[#This Row],[Renewables RTM Analysis]]=1),INDEX(Definitions!$C$21:$C$37,MATCH(Table3[[#Headers],[Renewables RTM Analysis]],Definitions!$A$21:$A$37,0)),AND(Table3[[#This Row],[Scale]:[Scale]]="Small",Table3[[#This Row],[Renewables RTM Analysis]]=1),INDEX(Definitions!$B$21:$B$37,MATCH(Table3[[#Headers],[Renewables RTM Analysis]],Definitions!$A$21:$A$37,0)),Table3[[#This Row],[Renewables RTM Analysis]]=0,0)} -> 20700 | AS4: {=_xlfn.IFS(AND(Table3[[#This Row],[Scale]:[Scale]]="Large",Table3[[#This Row],[Renewables Forecasts]]=1),INDEX(Definitions!$C$21:$C$37,MATCH(Table3[[#Headers],[Renewables Forecasts]],Definitions!$A$21:$A$37,0)),AND(Table3[[#This Row],[Scale]:[Scale]]="Small",Table3[[#This Row],[Renewables Forecasts]]=1),INDEX(Definitions!$B$21:$B$37,MATCH(Table3[[#Headers],[Renewables Forecasts]],Definitions!$A$21:$A$37,0)),Table3[[#This Row],[Renewables Forecasts]]=0,0)} -> 59400 | AT4: {=_xlfn.IFS(AND(Table3[[#This Row],[Scale]:[Scale]]="Large",Table3[[#This Row],[Renewables Regulation]]=1),INDEX(Definitions!$C$21:$C$37,MATCH(Table3[[#Headers],[Renewables Regulation]],Definitions!$A$21:$A$37,0)),AND(Table3[[#This Row],[Scale]:[Scale]]="Small",Table3[[#This Row],[Renewables Regulation]]=1),INDEX(Definitions!$B$21:$B$37,MATCH(Table3[[#Headers],[Renewables Regulation]],Definitions!$A$21:$A$37,0)),Table3[[#This Row],[Renewables Regulation]]=0,0)} -> 26100 | AU4: {=_xlfn.IFS(AND(Table3[[#This Row],[Scale]:[Scale]]="Large",Table3[[#This Row],[Flexibility Market Intelligence]]=1),INDEX(Definitions!$C$21:$C$37,MATCH(Table3[[#Headers],[Flexibility Market Intelligence]],Definitions!$A$21:$A$37,0)),AND(Table3[[#This Row],[Scale]:[Scale]]="Small",Table3[[#This Row],[Flexibility Market Intelligence]]=1),INDEX(Definitions!$B$21:$B$37,MATCH(Table3[[#Headers],[Flexibility Market Intelligence]],Definitions!$A$21:$A$37,0)),Table3[[#This Row],[Flexibility Market Intelligence]]=0,0)} -> 29700 | AV4: {=_xlfn.IFS(AND(Table3[[#This Row],[Scale]:[Scale]]="Large",Table3[[#This Row],[Flexibility RTM Analysis]]=1),INDEX(Definitions!$C$21:$C$37,MATCH(Table3[[#Headers],[Flexibility RTM Analysis]],Definitions!$A$21:$A$37,0)),AND(Table3[[#This Row],[Scale]:[Scale]]="Small",Table3[[#This Row],[Flexibility RTM Analysis]]=1),INDEX(Definitions!$B$21:$B$37,MATCH(Table3[[#Headers],[Flexibility RTM Analysis]],Definitions!$A$21:$A$37,0)),Table3[[#This Row],[Flexibility RTM Analysis]]=0,0)} -> 10800 | AW4: {=_xlfn.IFS(AND(Table3[[#This Row],[Scale]:[Scale]]="Large",Table3[[#This Row],[Flexibility Forecasts]]=1),INDEX(Definitions!$C$21:$C$37,MATCH(Table3[[#Headers],[Flexibility Forecasts]],Definitions!$A$21:$A$37,0)),AND(Table3[[#This Row],[Scale]:[Scale]]="Small",Table3[[#This Row],[Flexibility Forecasts]]=1),INDEX(Definitions!$B$21:$B$37,MATCH(Table3[[#Headers],[Flexibility Forecasts]],Definitions!$A$21:$A$37,0)),Table3[[#This Row],[Flexibility Forecasts]]=0,0)} -> 44100 | AX4: {=_xlfn.IFS(AND(Table3[[#This Row],[Scale]:[Scale]]="Large",Table3[[#This Row],[Flexibility Regulation]]=1),INDEX(Definitions!$C$21:$C$37,MATCH(Table3[[#Headers],[Flexibility Regulation]],Definitions!$A$21:$A$37,0)),AND(Table3[[#This Row],[Scale]:[Scale]]="Small",Table3[[#This Row],[Flexibility Regulation]]=1),INDEX(Definitions!$B$21:$B$37,MATCH(Table3[[#Headers],[Flexibility Regulation]],Definitions!$A$21:$A$37,0)),Table3[[#This Row],[Flexibility Regulation]]=0,0)} -> 36000 | AY4: {=_xlfn.IFS(AND(Table3[[#This Row],[Scale]:[Scale]]="Large",Table3[[#This Row],[Business Energy Essentials]]=1),INDEX(Definitions!$C$21:$C$37,MATCH(Table3[[#Headers],[Business Energy Essentials]],Definitions!$A$21:$A$37,0)),AND(Table3[[#This Row],[Scale]:[Scale]]="Small",Table3[[#This Row],[Business Energy Essentials]]=1),INDEX(Definitions!$B$21:$B$37,MATCH(Table3[[#Headers],[Business Energy Essentials]],Definitions!$A$21:$A$37,0)),Table3[[#This Row],[Business Energy Essentials]]=0,0)} -> 0 | AZ4: {=_xlfn.IFS(AND(Table3[[#This Row],[Scale]:[Scale]]="Large",Table3[[#This Row],[Energy User RTM Analysis]]=1),INDEX(Definitions!$C$21:$C$37,MATCH(Table3[[#Headers],[Energy User RTM Analysis]],Definitions!$A$21:$A$37,0)),AND(Table3[[#This Row],[Scale]:[Scale]]="Small",Table3[[#This Row],[Energy User RTM Analysis]]=1),INDEX(Definitions!$B$21:$B$37,MATCH(Table3[[#Headers],[Energy User RTM Analysis]],Definitions!$A$21:$A$37,0)),Table3[[#This Row],[Energy User RTM Analysis]]=0,0)} -> 0 | BA4: {=_xlfn.IFS(AND(Table3[[#This Row],[Scale]:[Scale]]="Large",Table3[[#This Row],[Energy User Forecasts]]=1),INDEX(Definitions!$C$21:$C$37,MATCH(Table3[[#Headers],[Energy User Forecasts]],Definitions!$A$21:$A$37,0)),AND(Table3[[#This Row],[Scale]:[Scale]]="Small",Table3[[#This Row],[Energy User Forecasts]]=1),INDEX(Definitions!$B$21:$B$37,MATCH(Table3[[#Headers],[Energy User Forecasts]],Definitions!$A$21:$A$37,0)),Table3[[#This Row],[Energy User Forecasts]]=0,0)} -> 0 | BB4: {=_xlfn.IFS(AND(Table3[[#This Row],[Scale]:[Scale]]="Large",Table3[[#This Row],[Energy User Regulation]]=1),INDEX(Definitions!$C$21:$C$37,MATCH(Table3[[#Headers],[Energy User Regulation]],Definitions!$A$21:$A$37,0)),AND(Table3[[#This Row],[Scale]:[Scale]]="Small",Table3[[#This Row],[Energy User Regulation]]=1),INDEX(Definitions!$B$21:$B$37,MATCH(Table3[[#Headers],[Energy User Regulation]],Definitions!$A$21:$A$37,0)),Table3[[#This Row],[Energy User Regulation]]=0,0)} -> 0 | BC4: =IF(SUM(Table3[[#This Row],[Column2]:[Column18]])>Table3[[#This Row],[Column19]],Table3[[#This Row],[Column19]],SUM(Table3[[#This Row],[Column2]:[Column18]])) -> 250000 | BD4: =Table3[[#This Row],[Total Spend]]/SUM(Table3[[#This Row],[Column2]:[Column18]]) -> 0.51824212
A5: Conrad Energy Limited | B5: Yes | C5: Yes | D5: 45566 | E5: Large | F5: =INDEX(Definitions!$G$13:$G$17,MATCH(Table3[[#This Row],[Propensity to buy/ buyer readiness]],Definitions!$A$13:$A$17,0)) -> 250000 | G5: 5 | H5: 5 | I5: 5 | J5: 5 | K5: 5 | L5: =SUM(Table3[[#This Row],[Strategic priority segment]:[Propensity to buy/ buyer readiness]]) -> 25 | M5: Flex Generation & Storage | N5: Flexibility generator/developer | O5: Energy traders | P5: Energy supplier | U5: 1 | V5: 1 | W5: 1 | X5: 1 | Y5: 1 | Z5: 0 | AA5: 1 | AB5: 0 | AC5: 0 | AD5: 1 | AE5: 1 | AF5: 1 | AG5: 1 | AH5: 0 | AI5: 0 | AJ5: 0 | AK5: 0 | AL5: {=_xlfn.IFS(AND(Table3[[#This Row],[Scale]:[Scale]]="Large",Table3[[#This Row],[Industry Essentials]]=1),INDEX(Definitions!$C$21:$C$37,MATCH(Table3[[#Headers],[Industry Essentials]],Definitions!$A$21:$A$37,0)),AND(Table3[[#This Row],[Scale]:[Scale]]="Small",Table3[[#This Row],[Industry Essentials]]=1),INDEX(Definitions!$B$21:$B$37,MATCH(Table3[[#Headers],[Industry Essentials]],Definitions!$A$21:$A$37,0)),Table3[[#This Row],[Industry Essentials]]=0,0)} -> 10800 | AM5: {=_xlfn.IFS(AND(Table3[[#This Row],[Scale]:[Scale]]="Large",Table3[[#This Row],[Energy Supply Market Intelligence]]=1),INDEX(Definitions!$C$21:$C$37,MATCH(Table3[[#Headers],[Energy Supply Market Intelligence]],Definitions!$A$21:$A$37,0)),AND(Table3[[#This Row],[Scale]:[Scale]]="Small",Table3[[#This Row],[Energy Supply Market Intelligence]]=1),INDEX(Definitions!$B$21:$B$37,MATCH(Table3[[#Headers],[Energy Supply Market Intelligence]],Definitions!$A$21:$A$37,0)),Table3[[#This Row],[Energy Supply Market Intelligence]]=0,0)} -> 43200 | AN5: {=_xlfn.IFS(AND(Table3[[#This Row],[Scale]:[Scale]]="Large",Table3[[#This Row],[Energy Supply RTM Analysis]]=1),INDEX(Definitions!$C$21:$C$37,MATCH(Table3[[#Headers],[Energy Supply RTM Analysis]],Definitions!$A$21:$A$37,0)),AND(Table3[[#This Row],[Scale]:[Scale]]="Small",Table3[[#This Row],[Energy Supply RTM Analysis]]=1),INDEX(Definitions!$B$21:$B$37,MATCH(Table3[[#Headers],[Energy Supply RTM Analysis]],Definitions!$A$21:$A$37,0)),Table3[[#This Row],[Energy Supply RTM Analysis]]=0,0)} -> 73800 | AO5: {=_xlfn.IFS(AND(Table3[[#This Row],[Scale]:[Scale]]="Large",Table3[[#This Row],[Energy Supply Forecasts]]=1),INDEX(Definitions!$C$21:$C$37,MATCH(Table3[[#Headers],[Energy Supply Forecasts]],Definitions!$A$21:$A$37,0)),AND(Table3[[#This Row],[Scale]:[Scale]]="Small",Table3[[#This Row],[Energy Supply Forecasts]]=1),INDEX(Definitions!$B$21:$B$37,MATCH(Table3[[#Headers],[Energy Supply Forecasts]],Definitions!$A$21:$A$37,0)),Table3[[#This Row],[Energy Supply Forecasts]]=0,0)} -> 48600 | AP5: {=_xlfn.IFS(AND(Table3[[#This Row],[Scale]:[Scale]]="Large",Table3[[#This Row],[Energy Supply Regulation]]=1),INDEX(Definitions!$C$21:$C$37,MATCH(Table3[[#Headers],[Energy Supply Regulation]],Definitions!$A$21:$A$37,0)),AND(Table3[[#This Row],[Scale]:[Scale]]="Small",Table3[[#This Row],[Energy Supply Regulation]]=1),INDEX(Definitions!$B$21:$B$37,MATCH(Table3[[#Headers],[Energy Supply Regulation]],Definitions!$A$21:$A$37,0)),Table3[[#This Row],[Energy Supply Regulation]]=0,0)} -> 55800 | AQ5: {=_xlfn.IFS(AND(Table3[[#This Row],[Scale]:[Scale]]="Large",Table3[[#This Row],[Renewables Market Intelligence]]=1),INDEX(Definitions!$C$21:$C$37,MATCH(Table3[[#Headers],[Renewables Market Intelligence]],Definitions!$A$21:$A$37,0)),AND(Table3[[#This Row],[Scale]:[Scale]]="Small",Table3[[#This Row],[Renewables Market Intelligence]]=1),INDEX(Definitions!$B$21:$B$37,MATCH(Table3[[#Headers],[Renewables Market Intelligence]],Definitions!$A$21:$A$37,0)),Table3[[#This Row],[Renewables Market Intelligence]]=0,0)} -> 0 | AR5: {=_xlfn.IFS(AND(Table3[[#This Row],[Scale]:[Scale]]="Large",Table3[[#This Row],[Renewables RTM Analysis]]=1),INDEX(Definitions!$C$21:$C$37,MATCH(Table3[[#Headers],[Renewables RTM Analysis]],Definitions!$A$21:$A$37,0)),AND(Table3[[#This Row],[Scale]:[Scale]]="Small",Table3[[#This Row],[Renewables RTM Analysis]]=1),INDEX(Definitions!$B$21:$B$37,MATCH(Table3[[#Headers],[Renewables RTM Analysis]],Definitions!$A$21:$A$37,0)),Table3[[#This Row],[Renewables RTM Analysis]]=0,0)} -> 20700 | AS5: {=_xlfn.IFS(AND(Table3[[#This Row],[Scale]:[Scale]]="Large",Table3[[#This Row],[Renewables Forecasts]]=1),INDEX(Definitions!$C$21:$C$37,MATCH(Table3[[#Headers],[Renewables Forecasts]],Definitions!$A$21:$A$37,0)),AND(Table3[[#This Row],[Scale]:[Scale]]="Small",Table3[[#This Row],[Renewables Forecasts]]=1),INDEX(Definitions!$B$21:$B$37,MATCH(Table3[[#Headers],[Renewables Forecasts]],Definitions!$A$21:$A$37,0)),Table3[[#This Row],[Renewables Forecasts]]=0,0)} -> 0 | AT5: {=_xlfn.IFS(AND(Table3[[#This Row],[Scale]:[Scale]]="Large",Table3[[#This Row],[Renewables Regulation]]=1),INDEX(Definitions!$C$21:$C$37,MATCH(Table3[[#Headers],[Renewables Regulation]],Definitions!$A$21:$A$37,0)),AND(Table3[[#This Row],[Scale]:[Scale]]="Small",Table3[[#This Row],[Renewables Regulation]]=1),INDEX(Definitions!$B$21:$B$37,MATCH(Table3[[#Headers],[Renewables Regulation]],Definitions!$A$21:$A$37,0)),Table3[[#This Row],[Renewables Regulation]]=0,0)} -> 0 | AU5: {=_xlfn.IFS(AND(Table3[[#This Row],[Scale]:[Scale]]="Large",Table3[[#This Row],[Flexibility Market Intelligence]]=1),INDEX(Definitions!$C$21:$C$37,MATCH(Table3[[#Headers],[Flexibility Market Intelligence]],Definitions!$A$21:$A$37,0)),AND(Table3[[#This Row],[Scale]:[Scale]]="Small",Table3[[#This Row],[Flexibility Market Intelligence]]=1),INDEX(Definitions!$B$21:$B$37,MATCH(Table3[[#Headers],[Flexibility Market Intelligence]],Definitions!$A$21:$A$37,0)),Table3[[#This Row],[Flexibility Market Intelligence]]=0,0)} -> 29700 | AV5: {=_xlfn.IFS(AND(Table3[[#This Row],[Scale]:[Scale]]="Large",Table3[[#This Row],[Flexibility RTM Analysis]]=1),INDEX(Definitions!$C$21:$C$37,MATCH(Table3[[#Headers],[Flexibility RTM Analysis]],Definitions!$A$21:$A$37,0)),AND(Table3[[#This Row],[Scale]:[Scale]]="Small",Table3[[#This Row],[Flexibility RTM Analysis]]=1),INDEX(Definitions!$B$21:$B$37,MATCH(Table3[[#Headers],[Flexibility RTM Analysis]],Definitions!$A$21:$A$37,0)),Table3[[#This Row],[Flexibility RTM Analysis]]=0,0)} -> 10800 | AW5: {=_xlfn.IFS(AND(Table3[[#This Row],[Scale]:[Scale]]="Large",Table3[[#This Row],[Flexibility Forecasts]]=1),INDEX(Definitions!$C$21:$C$37,MATCH(Table3[[#Headers],[Flexibility Forecasts]],Definitions!$A$21:$A$37,0)),AND(Table3[[#This Row],[Scale]:[Scale]]="Small",Table3[[#This Row],[Flexibility Forecasts]]=1),INDEX(Definitions!$B$21:$B$37,MATCH(Table3[[#Headers],[Flexibility Forecasts]],Definitions!$A$21:$A$37,0)),Table3[[#This Row],[Flexibility Forecasts]]=0,0)} -> 44100 | AX5: {=_xlfn.IFS(AND(Table3[[#This Row],[Scale]:[Scale]]="Large",Table3[[#This Row],[Flexibility Regulation]]=1),INDEX(Definitions!$C$21:$C$37,MATCH(Table3[[#Headers],[Flexibility Regulation]],Definitions!$A$21:$A$37,0)),AND(Table3[[#This Row],[Scale]:[Scale]]="Small",Table3[[#This Row],[Flexibility Regulation]]=1),INDEX(Definitions!$B$21:$B$37,MATCH(Table3[[#Headers],[Flexibility Regulation]],Definitions!$A$21:$A$37,0)),Table3[[#This Row],[Flexibility Regulation]]=0,0)} -> 36000 | AY5: {=_xlfn.IFS(AND(Table3[[#This Row],[Scale]:[Scale]]="Large",Table3[[#This Row],[Business Energy Essentials]]=1),INDEX(Definitions!$C$21:$C$37,MATCH(Table3[[#Headers],[Business Energy Essentials]],Definitions!$A$21:$A$37,0)),AND(Table3[[#This Row],[Scale]:[Scale]]="Small",Table3[[#This Row],[Business Energy Essentials]]=1),INDEX(Definitions!$B$21:$B$37,MATCH(Table3[[#Headers],[Business Energy Essentials]],Definitions!$A$21:$A$37,0)),Table3[[#This Row],[Business Energy Essentials]]=0,0)} -> 0 | AZ5: {=_xlfn.IFS(AND(Table3[[#This Row],[Scale]:[Scale]]="Large",Table3[[#This Row],[Energy User RTM Analysis]]=1),INDEX(Definitions!$C$21:$C$37,MATCH(Table3[[#Headers],[Energy User RTM Analysis]],Definitions!$A$21:$A$37,0)),AND(Table3[[#This Row],[Scale]:[Scale]]="Small",Table3[[#This Row],[Energy User RTM Analysis]]=1),INDEX(Definitions!$B$21:$B$37,MATCH(Table3[[#Headers],[Energy User RTM Analysis]],Definitions!$A$21:$A$37,0)),Table3[[#This Row],[Energy User RTM Analysis]]=0,0)} -> 0 | BA5: {=_xlfn.IFS(AND(Table3[[#This Row],[Scale]:[Scale]]="Large",Table3[[#This Row],[Energy User Forecasts]]=1),INDEX(Definitions!$C$21:$C$37,MATCH(Table3[[#Headers],[Energy User Forecasts]],Definitions!$A$21:$A$37,0)),AND(Table3[[#This Row],[Scale]:[Scale]]="Small",Table3[[#This Row],[Energy User Forecasts]]=1),INDEX(Definitions!$B$21:$B$37,MATCH(Table3[[#Headers],[Energy User Forecasts]],Definitions!$A$21:$A$37,0)),Table3[[#This Row],[Energy User Forecasts]]=0,0)} -> 0 | BB5: {=_xlfn.IFS(AND(Table3[[#This Row],[Scale]:[Scale]]="Large",Table3[[#This Row],[Energy User Regulation]]=1),INDEX(Definitions!$C$21:$C$37,MATCH(Table3[[#Headers],[Energy User Regulation]],Definitions!$A$21:$A$37,0)),AND(Table3[[#This Row],[Scale]:[Scale]]="Small",Table3[[#This Row],[Energy User Regulation]]=1),INDEX(Definitions!$B$21:$B$37,MATCH(Table3[[#Headers],[Energy User Regulation]],Definitions!$A$21:$A$37,0)),Table3[[#This Row],[Energy User Regulation]]=0,0)} -> 0 | BC5: =IF(SUM(Table3[[#This Row],[Column2]:[Column18]])>Table3[[#This Row],[Column19]],Table3[[#This Row],[Column19]],SUM(Table3[[#This Row],[Column2]:[Column18]])) -> 250000 | BD5: =Table3[[#This Row],[Total Spend]]/SUM(Table3[[#This Row],[Column2]:[Column18]]) -> 0.66934404
A6: Corona Energy Retail 1 Ltd | B6: Yes | D6: 45566 | E6: Large | F6: =INDEX(Definitions!$G$13:$G$17,MATCH(Table3[[#This Row],[Propensity to buy/ buyer readiness]],Definitions!$A$13:$A$17,0)) -> 250000 | G6: 5 | H6: 5 | I6: 5 | J6: 5 | K6: 5 | L6: =SUM(Table3[[#This Row],[Strategic priority segment]:[Propensity to buy/ buyer readiness]]) -> 25 | M6: Energy Supply | N6: Energy supplier | O6: Energy traders | U6: 1 | V6: 1 | W6: 1 | X6: 1 | Y6: 1 | Z6: 0 | AA6: 1 | AB6: 0 | AC6: 0 | AD6: 1 | AE6: 1 | AF6: 1 | AG6: 0 | AH6: 0 | AI6: 0 | AJ6: 0 | AK6: 0 | AL6: {=_xlfn.IFS(AND(Table3[[#This Row],[Scale]:[Scale]]="Large",Table3[[#This Row],[Industry Essentials]]=1),INDEX(Definitions!$C$21:$C$37,MATCH(Table3[[#Headers],[Industry Essentials]],Definitions!$A$21:$A$37,0)),AND(Table3[[#This Row],[Scale]:[Scale]]="Small",Table3[[#This Row],[Industry Essentials]]=1),INDEX(Definitions!$B$21:$B$37,MATCH(Table3[[#Headers],[Industry Essentials]],Definitions!$A$21:$A$37,0)),Table3[[#This Row],[Industry Essentials]]=0,0)} -> 10800 | AM6: {=_xlfn.IFS(AND(Table3[[#This Row],[Scale]:[Scale]]="Large",Table3[[#This Row],[Energy Supply Market Intelligence]]=1),INDEX(Definitions!$C$21:$C$37,MATCH(Table3[[#Headers],[Energy Supply Market Intelligence]],Definitions!$A$21:$A$37,0)),AND(Table3[[#This Row],[Scale]:[Scale]]="Small",Table3[[#This Row],[Energy Supply Market Intelligence]]=1),INDEX(Definitions!$B$21:$B$37,MATCH(Table3[[#Headers],[Energy Supply Market Intelligence]],Definitions!$A$21:$A$37,0)),Table3[[#This Row],[Energy Supply Market Intelligence]]=0,0)} -> 43200 | AN6: {=_xlfn.IFS(AND(Table3[[#This Row],[Scale]:[Scale]]="Large",Table3[[#This Row],[Energy Supply RTM Analysis]]=1),INDEX(Definitions!$C$21:$C$37,MATCH(Table3[[#Headers],[Energy Supply RTM Analysis]],Definitions!$A$21:$A$37,0)),AND(Table3[[#This Row],[Scale]:[Scale]]="Small",Table3[[#This Row],[Energy Supply RTM Analysis]]=1),INDEX(Definitions!$B$21:$B$37,MATCH(Table3[[#Headers],[Energy Supply RTM Analysis]],Definitions!$A$21:$A$37,0)),Table3[[#This Row],[Energy Supply RTM Analysis]]=0,0)} -> 73800 | AO6: {=_xlfn.IFS(AND(Table3[[#This Row],[Scale]:[Scale]]="Large",Table3[[#This Row],[Energy Supply Forecasts]]=1),INDEX(Definitions!$C$21:$C$37,MATCH(Table3[[#Headers],[Energy Supply Forecasts]],Definitions!$A$21:$A$37,0)),AND(Table3[[#This Row],[Scale]:[Scale]]="Small",Table3[[#This Row],[Energy Supply Forecasts]]=1),INDEX(Definitions!$B$21:$B$37,MATCH(Table3[[#Headers],[Energy Supply Forecasts]],Definitions!$A$21:$A$37,0)),Table3[[#This Row],[Energy Supply Forecasts]]=0,0)} -> 48600 | AP6: {=_xlfn.IFS(AND(Table3[[#This Row],[Scale]:[Scale]]="Large",Table3[[#This Row],[Energy Supply Regulation]]=1),INDEX(Definitions!$C$21:$C$37,MATCH(Table3[[#Headers],[Energy Supply Regulation]],Definitions!$A$21:$A$37,0)),AND(Table3[[#This Row],[Scale]:[Scale]]="Small",Table3[[#This Row],[Energy Supply Regulation]]=1),INDEX(Definitions!$B$21:$B$37,MATCH(Table3[[#Headers],[Energy Supply Regulation]],Definitions!$A$21:$A$37,0)),Table3[[#This Row],[Energy Supply Regulation]]=0,0)} -> 55800 | AQ6: {=_xlfn.IFS(AND(Table3[[#This Row],[Scale]:[Scale]]="Large",Table3[[#This Row],[Renewables Market Intelligence]]=1),INDEX(Definitions!$C$21:$C$37,MATCH(Table3[[#Headers],[Renewables Market Intelligence]],Definitions!$A$21:$A$37,0)),AND(Table3[[#This Row],[Scale]:[Scale]]="Small",Table3[[#This Row],[Renewables Market Intelligence]]=1),INDEX(Definitions!$B$21:$B$37,MATCH(Table3[[#Headers],[Renewables Market Intelligence]],Definitions!$A$21:$A$37,0)),Table3[[#This Row],[Renewables Market Intelligence]]=0,0)} -> 0 | AR6: {=_xlfn.IFS(AND(Table3[[#This Row],[Scale]:[Scale]]="Large",Table3[[#This Row],[Renewables RTM Analysis]]=1),INDEX(Definitions!$C$21:$C$37,MATCH(Table3[[#Headers],[Renewables RTM Analysis]],Definitions!$A$21:$A$37,0)),AND(Table3[[#This Row],[Scale]:[Scale]]="Small",Table3[[#This Row],[Renewables RTM Analysis]]=1),INDEX(Definitions!$B$21:$B$37,MATCH(Table3[[#Headers],[Renewables RTM Analysis]],Definitions!$A$21:$A$37,0)),Table3[[#This Row],[Renewables RTM Analysis]]=0,0)} -> 20700 | AS6: {=_xlfn.IFS(AND(Table3[[#This Row],[Scale]:[Scale]]="Large",Table3[[#This Row],[Renewables Forecasts]]=1),INDEX(Definitions!$C$21:$C$37,MATCH(Table3[[#Headers],[Renewables Forecasts]],Definitions!$A$21:$A$37,0)),AND(Table3[[#This Row],[Scale]:[Scale]]="Small",Table3[[#This Row],[Renewables Forecasts]]=1),INDEX(Definitions!$B$21:$B$37,MATCH(Table3[[#Headers],[Renewables Forecasts]],Definitions!$A$21:$A$37,0)),Table3[[#This Row],[Renewables Forecasts]]=0,0)} -> 0 | AT6: {=_xlfn.IFS(AND(Table3[[#This Row],[Scale]:[Scale]]="Large",Table3[[#This Row],[Renewables Regulation]]=1),INDEX(Definitions!$C$21:$C$37,MATCH(Table3[[#Headers],[Renewables Regulation]],Definitions!$A$21:$A$37,0)),AND(Table3[[#This Row],[Scale]:[Scale]]="Small",Table3[[#This Row],[Renewables Regulation]]=1),INDEX(Definitions!$B$21:$B$37,MATCH(Table3[[#Headers],[Renewables Regulation]],Definitions!$A$21:$A$37,0)),Table3[[#This Row],[Renewables Regulation]]=0,0)} -> 0 | AU6: {=_xlfn.IFS(AND(Table3[[#This Row],[Scale]:[Scale]]="Large",Table3[[#This Row],[Flexibility Market Intelligence]]=1),INDEX(Definitions!$C$21:$C$37,MATCH(Table3[[#Headers],[Flexibility Market Intelligence]],Definitions!$A$21:$A$37,0)),AND(Table3[[#This Row],[Scale]:[Scale]]="Small",Table3[[#This Row],[Flexibility Market Intelligence]]=1),INDEX(Definitions!$B$21:$B$37,MATCH(Table3[[#Headers],[Flexibility Market Intelligence]],Definitions!$A$21:$A$37,0)),Table3[[#This Row],[Flexibility Market Intelligence]]=0,0)} -> 29700 | AV6: {=_xlfn.IFS(AND(Table3[[#This Row],[Scale]:[Scale]]="Large",Table3[[#This Row],[Flexibility RTM Analysis]]=1),INDEX(Definitions!$C$21:$C$37,MATCH(Table3[[#Headers],[Flexibility RTM Analysis]],Definitions!$A$21:$A$37,0)),AND(Table3[[#This Row],[Scale]:[Scale]]="Small",Table3[[#This Row],[Flexibility RTM Analysis]]=1),INDEX(Definitions!$B$21:$B$37,MATCH(Table3[[#Headers],[Flexibility RTM Analysis]],Definitions!$A$21:$A$37,0)),Table3[[#This Row],[Flexibility RTM Analysis]]=0,0)} -> 10800 | AW6: {=_xlfn.IFS(AND(Table3[[#This Row],[Scale]:[Scale]]="Large",Table3[[#This Row],[Flexibility Forecasts]]=1),INDEX(Definitions!$C$21:$C$37,MATCH(Table3[[#Headers],[Flexibility Forecasts]],Definitions!$A$21:$A$37,0)),AND(Table3[[#This Row],[Scale]:[Scale]]="Small",Table3[[#This Row],[Flexibility Forecasts]]=1),INDEX(Definitions!$B$21:$B$37,MATCH(Table3[[#Headers],[Flexibility Forecasts]],Definitions!$A$21:$A$37,0)),Table3[[#This Row],[Flexibility Forecasts]]=0,0)} -> 44100 | AX6: {=_xlfn.IFS(AND(Table3[[#This Row],[Scale]:[Scale]]="Large",Table3[[#This Row],[Flexibility Regulation]]=1),INDEX(Definitions!$C$21:$C$37,MATCH(Table3[[#Headers],[Flexibility Regulation]],Definitions!$A$21:$A$37,0)),AND(Table3[[#This Row],[Scale]:[Scale]]="Small",Table3[[#This Row],[Flexibility Regulation]]=1),INDEX(Definitions!$B$21:$B$37,MATCH(Table3[[#Headers],[Flexibility Regulation]],Definitions!$A$21:$A$37,0)),Table3[[#This Row],[Flexibility Regulation]]=0,0)} -> 0 | AY6: {=_xlfn.IFS(AND(Table3[[#This Row],[Scale]:[Scale]]="Large",Table3[[#This Row],[Business Energy Essentials]]=1),INDEX(Definitions!$C$21:$C$37,MATCH(Table3[[#Headers],[Business Energy Essentials]],Definitions!$A$21:$A$37,0)),AND(Table3[[#This Row],[Scale]:[Scale]]="Small",Table3[[#This Row],[Business Energy Essentials]]=1),INDEX(Definitions!$B$21:$B$37,MATCH(Table3[[#Headers],[Business Energy Essentials]],Definitions!$A$21:$A$37,0)),Table3[[#This Row],[Business Energy Essentials]]=0,0)} -> 0 | AZ6: {=_xlfn.IFS(AND(Table3[[#This Row],[Scale]:[Scale]]="Large",Table3[[#This Row],[Energy User RTM Analysis]]=1),INDEX(Definitions!$C$21:$C$37,MATCH(Table3[[#Headers],[Energy User RTM Analysis]],Definitions!$A$21:$A$37,0)),AND(Table3[[#This Row],[Scale]:[Scale]]="Small",Table3[[#This Row],[Energy User RTM Analysis]]=1),INDEX(Definitions!$B$21:$B$37,MATCH(Table3[[#Headers],[Energy User RTM Analysis]],Definitions!$A$21:$A$37,0)),Table3[[#This Row],[Energy User RTM Analysis]]=0,0)} -> 0 | BA6: {=_xlfn.IFS(AND(Table3[[#This Row],[Scale]:[Scale]]="Large",Table3[[#This Row],[Energy User Forecasts]]=1),INDEX(Definitions!$C$21:$C$37,MATCH(Table3[[#Headers],[Energy User Forecasts]],Definitions!$A$21:$A$37,0)),AND(Table3[[#This Row],[Scale]:[Scale]]="Small",Table3[[#This Row],[Energy User Forecasts]]=1),INDEX(Definitions!$B$21:$B$37,MATCH(Table3[[#Headers],[Energy User Forecasts]],Definitions!$A$21:$A$37,0)),Table3[[#This Row],[Energy User Forecasts]]=0,0)} -> 0 | BB6: {=_xlfn.IFS(AND(Table3[[#This Row],[Scale]:[Scale]]="Large",Table3[[#This Row],[Energy User Regulation]]=1),INDEX(Definitions!$C$21:$C$37,MATCH(Table3[[#Headers],[Energy User Regulation]],Definitions!$A$21:$A$37,0)),AND(Table3[[#This Row],[Scale]:[Scale]]="Small",Table3[[#This Row],[Energy User Regulation]]=1),INDEX(Definitions!$B$21:$B$37,MATCH(Table3[[#Headers],[Energy User Regulation]],Definitions!$A$21:$A$37,0)),Table3[[#This Row],[Energy User Regulation]]=0,0)} -> 0 | BC6: =IF(SUM(Table3[[#This Row],[Column2]:[Column18]])>Table3[[#This Row],[Column19]],Table3[[#This Row],[Column19]],SUM(Table3[[#This Row],[Column2]:[Column18]])) -> 250000 | BD6: =Table3[[#This Row],[Total Spend]]/SUM(Table3[[#This Row],[Column2]:[Column18]]) -> 0.74074074
A7: Drax Power Limited | B7: Yes | D7: 45566 | E7: Large | F7: =INDEX(Definitions!$G$13:$G$17,MATCH(Table3[[#This Row],[Propensity to buy/ buyer readiness]],Definitions!$A$13:$A$17,0)) -> 250000 | G7: 5 | H7: 5 | I7: 5 | J7: 5 | K7: 5 | L7: =SUM(Table3[[#This Row],[Strategic priority segment]:[Propensity to buy/ buyer readiness]]) -> 25 | M7: Flex Generation & Storage | N7: Flexibility generator/developer | O7: Renewables generator/developer | P7: Energy supplier | Q7: Energy traders | U7: 1 | V7: 1 | W7: 1 | X7: 1 | Y7: 1 | Z7: 1 | AA7: 1 | AB7: 1 | AC7: 1 | AD7: 1 | AE7: 1 | AF7: 1 | AG7: 1 | AH7: 0 | AI7: 0 | AJ7: 0 | AK7: 0 | AL7: {=_xlfn.IFS(AND(Table3[[#This Row],[Scale]:[Scale]]="Large",Table3[[#This Row],[Industry Essentials]]=1),INDEX(Definitions!$C$21:$C$37,MATCH(Table3[[#Headers],[Industry Essentials]],Definitions!$A$21:$A$37,0)),AND(Table3[[#This Row],[Scale]:[Scale]]="Small",Table3[[#This Row],[Industry Essentials]]=1),INDEX(Definitions!$B$21:$B$37,MATCH(Table3[[#Headers],[Industry Essentials]],Definitions!$A$21:$A$37,0)),Table3[[#This Row],[Industry Essentials]]=0,0)} -> 10800 | AM7: {=_xlfn.IFS(AND(Table3[[#This Row],[Scale]:[Scale]]="Large",Table3[[#This Row],[Energy Supply Market Intelligence]]=1),INDEX(Definitions!$C$21:$C$37,MATCH(Table3[[#Headers],[Energy Supply Market Intelligence]],Definitions!$A$21:$A$37,0)),AND(Table3[[#This Row],[Scale]:[Scale]]="Small",Table3[[#This Row],[Energy Supply Market Intelligence]]=1),INDEX(Definitions!$B$21:$B$37,MATCH(Table3[[#Headers],[Energy Supply Market Intelligence]],Definitions!$A$21:$A$37,0)),Table3[[#This Row],[Energy Supply Market Intelligence]]=0,0)} -> 43200 | AN7: {=_xlfn.IFS(AND(Table3[[#This Row],[Scale]:[Scale]]="Large",Table3[[#This Row],[Energy Supply RTM Analysis]]=1),INDEX(Definitions!$C$21:$C$37,MATCH(Table3[[#Headers],[Energy Supply RTM Analysis]],Definitions!$A$21:$A$37,0)),AND(Table3[[#This Row],[Scale]:[Scale]]="Small",Table3[[#This Row],[Energy Supply RTM Analysis]]=1),INDEX(Definitions!$B$21:$B$37,MATCH(Table3[[#Headers],[Energy Supply RTM Analysis]],Definitions!$A$21:$A$37,0)),Table3[[#This Row],[Energy Supply RTM Analysis]]=0,0)} -> 73800 | AO7: {=_xlfn.IFS(AND(Table3[[#This Row],[Scale]:[Scale]]="Large",Table3[[#This Row],[Energy Supply Forecasts]]=1),INDEX(Definitions!$C$21:$C$37,MATCH(Table3[[#Headers],[Energy Supply Forecasts]],Definitions!$A$21:$A$37,0)),AND(Table3[[#This Row],[Scale]:[Scale]]="Small",Table3[[#This Row],[Energy Supply Forecasts]]=1),INDEX(Definitions!$B$21:$B$37,MATCH(Table3[[#Headers],[Energy Supply Forecasts]],Definitions!$A$21:$A$37,0)),Table3[[#This Row],[Energy Supply Forecasts]]=0,0)} -> 48600 | AP7: {=_xlfn.IFS(AND(Table3[[#This Row],[Scale]:[Scale]]="Large",Table3[[#This Row],[Energy Supply Regulation]]=1),INDEX(Definitions!$C$21:$C$37,MATCH(Table3[[#Headers],[Energy Supply Regulation]],Definitions!$A$21:$A$37,0)),AND(Table3[[#This Row],[Scale]:[Scale]]="Small",Table3[[#This Row],[Energy Supply Regulation]]=1),INDEX(Definitions!$B$21:$B$37,MATCH(Table3[[#Headers],[Energy Supply Regulation]],Definitions!$A$21:$A$37,0)),Table3[[#This Row],[Energy Supply Regulation]]=0,0)} -> 55800 | AQ7: {=_xlfn.IFS(AND(Table3[[#This Row],[Scale]:[Scale]]="Large",Table3[[#This Row],[Renewables Market Intelligence]]=1),INDEX(Definitions!$C$21:$C$37,MATCH(Table3[[#Headers],[Renewables Market Intelligence]],Definitions!$A$21:$A$37,0)),AND(Table3[[#This Row],[Scale]:[Scale]]="Small",Table3[[#This Row],[Renewables Market Intelligence]]=1),INDEX(Definitions!$B$21:$B$37,MATCH(Table3[[#Headers],[Renewables Market Intelligence]],Definitions!$A$21:$A$37,0)),Table3[[#This Row],[Renewables Market Intelligence]]=0,0)} -> 23400 | AR7: {=_xlfn.IFS(AND(Table3[[#This Row],[Scale]:[Scale]]="Large",Table3[[#This Row],[Renewables RTM Analysis]]=1),INDEX(Definitions!$C$21:$C$37,MATCH(Table3[[#Headers],[Renewables RTM Analysis]],Definitions!$A$21:$A$37,0)),AND(Table3[[#This Row],[Scale]:[Scale]]="Small",Table3[[#This Row],[Renewables RTM Analysis]]=1),INDEX(Definitions!$B$21:$B$37,MATCH(Table3[[#Headers],[Renewables RTM Analysis]],Definitions!$A$21:$A$37,0)),Table3[[#This Row],[Renewables RTM Analysis]]=0,0)} -> 20700 | AS7: {=_xlfn.IFS(AND(Table3[[#This Row],[Scale]:[Scale]]="Large",Table3[[#This Row],[Renewables Forecasts]]=1),INDEX(Definitions!$C$21:$C$37,MATCH(Table3[[#Headers],[Renewables Forecasts]],Definitions!$A$21:$A$37,0)),AND(Table3[[#This Row],[Scale]:[Scale]]="Small",Table3[[#This Row],[Renewables Forecasts]]=1),INDEX(Definitions!$B$21:$B$37,MATCH(Table3[[#Headers],[Renewables Forecasts]],Definitions!$A$21:$A$37,0)),Table3[[#This Row],[Renewables Forecasts]]=0,0)} -> 59400 | AT7: {=_xlfn.IFS(AND(Table3[[#This Row],[Scale]:[Scale]]="Large",Table3[[#This Row],[Renewables Regulation]]=1),INDEX(Definitions!$C$21:$C$37,MATCH(Table3[[#Headers],[Renewables Regulation]],Definitions!$A$21:$A$37,0)),AND(Table3[[#This Row],[Scale]:[Scale]]="Small",Table3[[#This Row],[Renewables Regulation]]=1),INDEX(Definitions!$B$21:$B$37,MATCH(Table3[[#Headers],[Renewables Regulation]],Definitions!$A$21:$A$37,0)),Table3[[#This Row],[Renewables Regulation]]=0,0)} -> 26100 | AU7: {=_xlfn.IFS(AND(Table3[[#This Row],[Scale]:[Scale]]="Large",Table3[[#This Row],[Flexibility Market Intelligence]]=1),INDEX(Definitions!$C$21:$C$37,MATCH(Table3[[#Headers],[Flexibility Market Intelligence]],Definitions!$A$21:$A$37,0)),AND(Table3[[#This Row],[Scale]:[Scale]]="Small",Table3[[#This Row],[Flexibility Market Intelligence]]=1),INDEX(Definitions!$B$21:$B$37,MATCH(Table3[[#Headers],[Flexibility Market Intelligence]],Definitions!$A$21:$A$37,0)),Table3[[#This Row],[Flexibility Market Intelligence]]=0,0)} -> 29700 | AV7: {=_xlfn.IFS(AND(Table3[[#This Row],[Scale]:[Scale]]="Large",Table3[[#This Row],[Flexibility RTM Analysis]]=1),INDEX(Definitions!$C$21:$C$37,MATCH(Table3[[#Headers],[Flexibility RTM Analysis]],Definitions!$A$21:$A$37,0)),AND(Table3[[#This Row],[Scale]:[Scale]]="Small",Table3[[#This Row],[Flexibility RTM Analysis]]=1),INDEX(Definitions!$B$21:$B$37,MATCH(Table3[[#Headers],[Flexibility RTM Analysis]],Definitions!$A$21:$A$37,0)),Table3[[#This Row],[Flexibility RTM Analysis]]=0,0)} -> 10800 | AW7: {=_xlfn.IFS(AND(Table3[[#This Row],[Scale]:[Scale]]="Large",Table3[[#This Row],[Flexibility Forecasts]]=1),INDEX(Definitions!$C$21:$C$37,MATCH(Table3[[#Headers],[Flexibility Forecasts]],Definitions!$A$21:$A$37,0)),AND(Table3[[#This Row],[Scale]:[Scale]]="Small",Table3[[#This Row],[Flexibility Forecasts]]=1),INDEX(Definitions!$B$21:$B$37,MATCH(Table3[[#Headers],[Flexibility Forecasts]],Definitions!$A$21:$A$37,0)),Table3[[#This Row],[Flexibility Forecasts]]=0,0)} -> 44100 | AX7: {=_xlfn.IFS(AND(Table3[[#This Row],[Scale]:[Scale]]="Large",Table3[[#This Row],[Flexibility Regulation]]=1),INDEX(Definitions!$C$21:$C$37,MATCH(Table3[[#Headers],[Flexibility Regulation]],Definitions!$A$21:$A$37,0)),AND(Table3[[#This Row],[Scale]:[Scale]]="Small",Table3[[#This Row],[Flexibility Regulation]]=1),INDEX(Definitions!$B$21:$B$37,MATCH(Table3[[#Headers],[Flexibility Regulation]],Definitions!$A$21:$A$37,0)),Table3[[#This Row],[Flexibility Regulation]]=0,0)} -> 36000 | AY7: {=_xlfn.IFS(AND(Table3[[#This Row],[Scale]:[Scale]]="Large",Table3[[#This Row],[Business Energy Essentials]]=1),INDEX(Definitions!$C$21:$C$37,MATCH(Table3[[#Headers],[Business Energy Essentials]],Definitions!$A$21:$A$37,0)),AND(Table3[[#This Row],[Scale]:[Scale]]="Small",Table3[[#This Row],[Business Energy Essentials]]=1),INDEX(Definitions!$B$21:$B$37,MATCH(Table3[[#Headers],[Business Energy Essentials]],Definitions!$A$21:$A$37,0)),Table3[[#This Row],[Business Energy Essentials]]=0,0)} -> 0 | AZ7: {=_xlfn.IFS(AND(Table3[[#This Row],[Scale]:[Scale]]="Large",Table3[[#This Row],[Energy User RTM Analysis]]=1),INDEX(Definitions!$C$21:$C$37,MATCH(Table3[[#Headers],[Energy User RTM Analysis]],Definitions!$A$21:$A$37,0)),AND(Table3[[#This Row],[Scale]:[Scale]]="Small",Table3[[#This Row],[Energy User RTM Analysis]]=1),INDEX(Definitions!$B$21:$B$37,MATCH(Table3[[#Headers],[Energy User RTM Analysis]],Definitions!$A$21:$A$37,0)),Table3[[#This Row],[Energy User RTM Analysis]]=0,0)} -> 0 | BA7: {=_xlfn.IFS(AND(Table3[[#This Row],[Scale]:[Scale]]="Large",Table3[[#This Row],[Energy User Forecasts]]=1),INDEX(Definitions!$C$21:$C$37,MATCH(Table3[[#Headers],[Energy User Forecasts]],Definitions!$A$21:$A$37,0)),AND(Table3[[#This Row],[Scale]:[Scale]]="Small",Table3[[#This Row],[Energy User Forecasts]]=1),INDEX(Definitions!$B$21:$B$37,MATCH(Table3[[#Headers],[Energy User Forecasts]],Definitions!$A$21:$A$37,0)),Table3[[#This Row],[Energy User Forecasts]]=0,0)} -> 0 | BB7: {=_xlfn.IFS(AND(Table3[[#This Row],[Scale]:[Scale]]="Large",Table3[[#This Row],[Energy User Regulation]]=1),INDEX(Definitions!$C$21:$C$37,MATCH(Table3[[#Headers],[Energy User Regulation]],Definitions!$A$21:$A$37,0)),AND(Table3[[#This Row],[Scale]:[Scale]]="Small",Table3[[#This Row],[Energy User Regulation]]=1),INDEX(Definitions!$B$21:$B$37,MATCH(Table3[[#Headers],[Energy User Regulation]],Definitions!$A$21:$A$37,0)),Table3[[#This Row],[Energy User Regulation]]=0,0)} -> 0 | BC7: =IF(SUM(Table3[[#This Row],[Column2]:[Column18]])>Table3[[#This Row],[Column19]],Table3[[#This Row],[Column19]],SUM(Table3[[#This Row],[Column2]:[Column18]])) -> 250000 | BD7: =Table3[[#This Row],[Total Spend]]/SUM(Table3[[#This Row],[Column2]:[Column18]]) -> 0.51824212
A8: E.ON Connecting Energies Ltd. | B8: Yes | D8: 45566 | E8: Large | F8: =INDEX(Definitions!$G$13:$G$17,MATCH(Table3[[#This Row],[Propensity to buy/ buyer readiness]],Definitions!$A$13:$A$17,0)) -> 250000 | G8: 5 | H8: 5 | I8: 5 | J8: 5 | K8: 5 | L8: =SUM(Table3[[#This Row],[Strategic priority segment]:[Propensity to buy/ buyer readiness]]) -> 25 | M8: Energy Supply | N8: Energy supplier | O8: Flexibility generator/developer | P8: Renewables generator/developer | Q8: Energy traders | U8: 1 | V8: 1 | W8: 1 | X8: 1 | Y8: 1 | Z8: 1 | AA8: 1 | AB8: 1 | AC8: 1 | AD8: 1 | AE8: 1 | AF8: 1 | AG8: 1 | AH8: 0 | AI8: 0 | AJ8: 0 | AK8: 0 | AL8: {=_xlfn.IFS(AND(Table3[[#This Row],[Scale]:[Scale]]="Large",Table3[[#This Row],[Industry Essentials]]=1),INDEX(Definitions!$C$21:$C$37,MATCH(Table3[[#Headers],[Industry Essentials]],Definitions!$A$21:$A$37,0)),AND(Table3[[#This Row],[Scale]:[Scale]]="Small",Table3[[#This Row],[Industry Essentials]]=1),INDEX(Definitions!$B$21:$B$37,MATCH(Table3[[#Headers],[Industry Essentials]],Definitions!$A$21:$A$37,0)),Table3[[#This Row],[Industry Essentials]]=0,0)} -> 10800 | AM8: {=_xlfn.IFS(AND(Table3[[#This Row],[Scale]:[Scale]]="Large",Table3[[#This Row],[Energy Supply Market Intelligence]]=1),INDEX(Definitions!$C$21:$C$37,MATCH(Table3[[#Headers],[Energy Supply Market Intelligence]],Definitions!$A$21:$A$37,0)),AND(Table3[[#This Row],[Scale]:[Scale]]="Small",Table3[[#This Row],[Energy Supply Market Intelligence]]=1),INDEX(Definitions!$B$21:$B$37,MATCH(Table3[[#Headers],[Energy Supply Market Intelligence]],Definitions!$A$21:$A$37,0)),Table3[[#This Row],[Energy Supply Market Intelligence]]=0,0)} -> 43200 | AN8: {=_xlfn.IFS(AND(Table3[[#This Row],[Scale]:[Scale]]="Large",Table3[[#This Row],[Energy Supply RTM Analysis]]=1),INDEX(Definitions!$C$21:$C$37,MATCH(Table3[[#Headers],[Energy Supply RTM Analysis]],Definitions!$A$21:$A$37,0)),AND(Table3[[#This Row],[Scale]:[Scale]]="Small",Table3[[#This Row],[Energy Supply RTM Analysis]]=1),INDEX(Definitions!$B$21:$B$37,MATCH(Table3[[#Headers],[Energy Supply RTM Analysis]],Definitions!$A$21:$A$37,0)),Table3[[#This Row],[Energy Supply RTM Analysis]]=0,0)} -> 73800 | AO8: {=_xlfn.IFS(AND(Table3[[#This Row],[Scale]:[Scale]]="Large",Table3[[#This Row],[Energy Supply Forecasts]]=1),INDEX(Definitions!$C$21:$C$37,MATCH(Table3[[#Headers],[Energy Supply Forecasts]],Definitions!$A$21:$A$37,0)),AND(Table3[[#This Row],[Scale]:[Scale]]="Small",Table3[[#This Row],[Energy Supply Forecasts]]=1),INDEX(Definitions!$B$21:$B$37,MATCH(Table3[[#Headers],[Energy Supply Forecasts]],Definitions!$A$21:$A$37,0)),Table3[[#This Row],[Energy Supply Forecasts]]=0,0)} -> 48600 | AP8: {=_xlfn.IFS(AND(Table3[[#This Row],[Scale]:[Scale]]="Large",Table3[[#This Row],[Energy Supply Regulation]]=1),INDEX(Definitions!$C$21:$C$37,MATCH(Table3[[#Headers],[Energy Supply Regulation]],Definitions!$A$21:$A$37,0)),AND(Table3[[#This Row],[Scale]:[Scale]]="Small",Table3[[#This Row],[Energy Supply Regulation]]=1),INDEX(Definitions!$B$21:$B$37,MATCH(Table3[[#Headers],[Energy Supply Regulation]],Definitions!$A$21:$A$37,0)),Table3[[#This Row],[Energy Supply Regulation]]=0,0)} -> 55800 | AQ8: {=_xlfn.IFS(AND(Table3[[#This Row],[Scale]:[Scale]]="Large",Table3[[#This Row],[Renewables Market Intelligence]]=1),INDEX(Definitions!$C$21:$C$37,MATCH(Table3[[#Headers],[Renewables Market Intelligence]],Definitions!$A$21:$A$37,0)),AND(Table3[[#This Row],[Scale]:[Scale]]="Small",Table3[[#This Row],[Renewables Market Intelligence]]=1),INDEX(Definitions!$B$21:$B$37,MATCH(Table3[[#Headers],[Renewables Market Intelligence]],Definitions!$A$21:$A$37,0)),Table3[[#This Row],[Renewables Market Intelligence]]=0,0)} -> 23400 | AR8: {=_xlfn.IFS(AND(Table3[[#This Row],[Scale]:[Scale]]="Large",Table3[[#This Row],[Renewables RTM Analysis]]=1),INDEX(Definitions!$C$21:$C$37,MATCH(Table3[[#Headers],[Renewables RTM Analysis]],Definitions!$A$21:$A$37,0)),AND(Table3[[#This Row],[Scale]:[Scale]]="Small",Table3[[#This Row],[Renewables RTM Analysis]]=1),INDEX(Definitions!$B$21:$B$37,MATCH(Table3[[#Headers],[Renewables RTM Analysis]],Definitions!$A$21:$A$37,0)),Table3[[#This Row],[Renewables RTM Analysis]]=0,0)} -> 20700 | AS8: {=_xlfn.IFS(AND(Table3[[#This Row],[Scale]:[Scale]]="Large",Table3[[#This Row],[Renewables Forecasts]]=1),INDEX(Definitions!$C$21:$C$37,MATCH(Table3[[#Headers],[Renewables Forecasts]],Definitions!$A$21:$A$37,0)),AND(Table3[[#This Row],[Scale]:[Scale]]="Small",Table3[[#This Row],[Renewables Forecasts]]=1),INDEX(Definitions!$B$21:$B$37,MATCH(Table3[[#Headers],[Renewables Forecasts]],Definitions!$A$21:$A$37,0)),Table3[[#This Row],[Renewables Forecasts]]=0,0)} -> 59400 | AT8: {=_xlfn.IFS(AND(Table3[[#This Row],[Scale]:[Scale]]="Large",Table3[[#This Row],[Renewables Regulation]]=1),INDEX(Definitions!$C$21:$C$37,MATCH(Table3[[#Headers],[Renewables Regulation]],Definitions!$A$21:$A$37,0)),AND(Table3[[#This Row],[Scale]:[Scale]]="Small",Table3[[#This Row],[Renewables Regulation]]=1),INDEX(Definitions!$B$21:$B$37,MATCH(Table3[[#Headers],[Renewables Regulation]],Definitions!$A$21:$A$37,0)),Table3[[#This Row],[Renewables Regulation]]=0,0)} -> 26100 | AU8: {=_xlfn.IFS(AND(Table3[[#This Row],[Scale]:[Scale]]="Large",Table3[[#This Row],[Flexibility Market Intelligence]]=1),INDEX(Definitions!$C$21:$C$37,MATCH(Table3[[#Headers],[Flexibility Market Intelligence]],Definitions!$A$21:$A$37,0)),AND(Table3[[#This Row],[Scale]:[Scale]]="Small",Table3[[#This Row],[Flexibility Market Intelligence]]=1),INDEX(Definitions!$B$21:$B$37,MATCH(Table3[[#Headers],[Flexibility Market Intelligence]],Definitions!$A$21:$A$37,0)),Table3[[#This Row],[Flexibility Market Intelligence]]=0,0)} -> 29700 | AV8: {=_xlfn.IFS(AND(Table3[[#This Row],[Scale]:[Scale]]="Large",Table3[[#This Row],[Flexibility RTM Analysis]]=1),INDEX(Definitions!$C$21:$C$37,MATCH(Table3[[#Headers],[Flexibility RTM Analysis]],Definitions!$A$21:$A$37,0)),AND(Table3[[#This Row],[Scale]:[Scale]]="Small",Table3[[#This Row],[Flexibility RTM Analysis]]=1),INDEX(Definitions!$B$21:$B$37,MATCH(Table3[[#Headers],[Flexibility RTM Analysis]],Definitions!$A$21:$A$37,0)),Table3[[#This Row],[Flexibility RTM Analysis]]=0,0)} -> 10800 | AW8: {=_xlfn.IFS(AND(Table3[[#This Row],[Scale]:[Scale]]="Large",Table3[[#This Row],[Flexibility Forecasts]]=1),INDEX(Definitions!$C$21:$C$37,MATCH(Table3[[#Headers],[Flexibility Forecasts]],Definitions!$A$21:$A$37,0)),AND(Table3[[#This Row],[Scale]:[Scale]]="Small",Table3[[#This Row],[Flexibility Forecasts]]=1),INDEX(Definitions!$B$21:$B$37,MATCH(Table3[[#Headers],[Flexibility Forecasts]],Definitions!$A$21:$A$37,0)),Table3[[#This Row],[Flexibility Forecasts]]=0,0)} -> 44100 | AX8: {=_xlfn.IFS(AND(Table3[[#This Row],[Scale]:[Scale]]="Large",Table3[[#This Row],[Flexibility Regulation]]=1),INDEX(Definitions!$C$21:$C$37,MATCH(Table3[[#Headers],[Flexibility Regulation]],Definitions!$A$21:$A$37,0)),AND(Table3[[#This Row],[Scale]:[Scale]]="Small",Table3[[#This Row],[Flexibility Regulation]]=1),INDEX(Definitions!$B$21:$B$37,MATCH(Table3[[#Headers],[Flexibility Regulation]],Definitions!$A$21:$A$37,0)),Table3[[#This Row],[Flexibility Regulation]]=0,0)} -> 36000 | AY8: {=_xlfn.IFS(AND(Table3[[#This Row],[Scale]:[Scale]]="Large",Table3[[#This Row],[Business Energy Essentials]]=1),INDEX(Definitions!$C$21:$C$37,MATCH(Table3[[#Headers],[Business Energy Essentials]],Definitions!$A$21:$A$37,0)),AND(Table3[[#This Row],[Scale]:[Scale]]="Small",Table3[[#This Row],[Business Energy Essentials]]=1),INDEX(Definitions!$B$21:$B$37,MATCH(Table3[[#Headers],[Business Energy Essentials]],Definitions!$A$21:$A$37,0)),Table3[[#This Row],[Business Energy Essentials]]=0,0)} -> 0 | AZ8: {=_xlfn.IFS(AND(Table3[[#This Row],[Scale]:[Scale]]="Large",Table3[[#This Row],[Energy User RTM Analysis]]=1),INDEX(Definitions!$C$21:$C$37,MATCH(Table3[[#Headers],[Energy User RTM Analysis]],Definitions!$A$21:$A$37,0)),AND(Table3[[#This Row],[Scale]:[Scale]]="Small",Table3[[#This Row],[Energy User RTM Analysis]]=1),INDEX(Definitions!$B$21:$B$37,MATCH(Table3[[#Headers],[Energy User RTM Analysis]],Definitions!$A$21:$A$37,0)),Table3[[#This Row],[Energy User RTM Analysis]]=0,0)} -> 0 | BA8: {=_xlfn.IFS(AND(Table3[[#This Row],[Scale]:[Scale]]="Large",Table3[[#This Row],[Energy User Forecasts]]=1),INDEX(Definitions!$C$21:$C$37,MATCH(Table3[[#Headers],[Energy User Forecasts]],Definitions!$A$21:$A$37,0)),AND(Table3[[#This Row],[Scale]:[Scale]]="Small",Table3[[#This Row],[Energy User Forecasts]]=1),INDEX(Definitions!$B$21:$B$37,MATCH(Table3[[#Headers],[Energy User Forecasts]],Definitions!$A$21:$A$37,0)),Table3[[#This Row],[Energy User Forecasts]]=0,0)} -> 0 | BB8: {=_xlfn.IFS(AND(Table3[[#This Row],[Scale]:[Scale]]="Large",Table3[[#This Row],[Energy User Regulation]]=1),INDEX(Definitions!$C$21:$C$37,MATCH(Table3[[#Headers],[Energy User Regulation]],Definitions!$A$21:$A$37,0)),AND(Table3[[#This Row],[Scale]:[Scale]]="Small",Table3[[#This Row],[Energy User Regulation]]=1),INDEX(Definitions!$B$21:$B$37,MATCH(Table3[[#Headers],[Energy User Regulation]],Definitions!$A$21:$A$37,0)),Table3[[#This Row],[Energy User Regulation]]=0,0)} -> 0 | BC8: =IF(SUM(Table3[[#This Row],[Column2]:[Column18]])>Table3[[#This Row],[Column19]],Table3[[#This Row],[Column19]],SUM(Table3[[#This Row],[Column2]:[Column18]])) -> 250000 | BD8: =Table3[[#This Row],[Total Spend]]/SUM(Table3[[#This Row],[Column2]:[Column18]]) -> 0.51824212
